<?xml version="1.0"?>
<sdf version="1.9">
  <model name="wave_glider">

    <link name="wave_glider_float_link">
      <inertial>
        <pose>0 0 -0.13 0 0 0</pose>
          <mass>71</mass>
          <inertia>
            <ixx>4.194916667</ixx>
            <ixy>0</ixy>
            <ixz>0</ixz>
            <iyy>55.35278333</iyy>
            <iyz>0</iyz>
            <izz>58.92171667</izz>
          </inertia>
      </inertial>
      <collision name="collision">
        <geometry>
          <mesh>
            <scale>1.0 1.0 1.0</scale>
            <uri>model://glider_wave/mesh/wave_glider_hull_collision.stl</uri>
          </mesh>
          <!-- <box>
            <size>3.05 0.81 0.23</size>
          </box> -->
        </geometry>
      </collision>
      <collision name="fin_collision">
        <geometry>
          <mesh>
            <scale>1.0 1.0 1.0</scale>
            <uri>model://glider_wave/mesh/wave_glider_fin_collision.stl</uri>
          </mesh>
        </geometry>
      </collision>
      <visual name="visual">
        <pose>0 0 0 0 0 0</pose>
        <geometry>
          <mesh>
            <scale>1.0 1.0 1.0</scale>
            <uri>model://glider_wave/mesh/wave_glider_hull.dae</uri>
          </mesh>
          <!-- <box>
            <size>3.05 0.81 0.23</size>
          </box> -->
        </geometry>
      </visual>
      <visual name="fin_visual">
        <pose>0 0 0 0 0 0</pose>
        <geometry>
          <mesh>
            <scale>1.0 1.0 1.0</scale>
            <uri>model://glider_wave/mesh/wave_glider_fin.dae</uri>
          </mesh>
        </geometry>
      </visual>
      <visual name="sensors_visual">
        <geometry>
          <mesh>
            <scale>1.0 1.0 1.0</scale>
            <uri>model://glider_wave/mesh/wave_glider_sensors.dae</uri>
          </mesh>
        </geometry>
      </visual>
      <visual name="umbilical_connection_visual">
        <geometry>
          <mesh>
            <scale>1.0 1.0 1.0</scale>
            <uri>model://glider_wave/mesh/wave_glider_umbilical_connection.dae</uri>
          </mesh>
        </geometry>
      </visual>
    </link>

    <link name="wave_glider_umbilical_joint_link">
      <inertial>
        <pose>0.23 0 -0.38 0 0 0</pose>
        <mass>0.5</mass>
        <inertia>
          <ixx>0.001</ixx>
          <ixy>0</ixy>
          <ixz>0</ixz>
          <iyy>0.001</iyy>
          <iyz>0</iyz>
          <izz>0.001</izz>
        </inertia>
      </inertial>
      <collision name="collision">
        <geometry>
          <box>
            <size>0.2 0.2 0.2</size>
          </box>
        </geometry>
      </collision>
      <visual name="visual">
        <geometry>
          <mesh>
            <scale>1.0 1.0 1.0</scale>
            <uri>model://glider_wave/mesh/wave_glider_umbilical_joint.dae</uri>
          </mesh>
        </geometry>
      </visual>
    </link>

    <joint name="wave_glider_umbilical_joint_joint" type="revolute">
        <pose>0.23 0 -0.38 0 0 0</pose>
        <child>wave_glider_umbilical_joint_link</child>
        <parent>wave_glider_float_link</parent>
        <axis>
          <limit>
            <lower>-0.8</lower>
            <upper>0.8</upper>
          </limit>
          <dynamics>
            <damping>0.1</damping>
          </dynamics>
          <xyz>1 0 0</xyz>
        </axis>
    </joint>

    <link name="wave_glider_umbilical_link">
      <inertial>
        <pose>0.23 0 -1.31 0 0 0</pose>
          <mass>0.5</mass>
          <inertia>
            <ixx>0.001</ixx>
            <ixy>0</ixy>
            <ixz>0</ixz>
            <iyy>0.001</iyy>
            <iyz>0</iyz>
            <izz>0.001</izz>
          </inertia>
      </inertial>
      <collision name="collision">
        <geometry>
          <mesh>
            <scale>1.0 1.0 1.0</scale>
            <uri>model://glider_wave/mesh/wave_glider_umbilical.dae</uri>
          </mesh>
        </geometry>
      </collision>
      <visual name="visual">
        <geometry>
          <mesh>
            <scale>1.0 1.0 1.0</scale>
            <uri>model://glider_wave/mesh/wave_glider_umbilical.dae</uri>
          </mesh>
        </geometry>
      </visual>
    </link>  

    <joint name="wave_glider_umbilical_joint" type="revolute">
        <pose>0.23 0 -0.46 0 0 0</pose>
        <child>wave_glider_umbilical_link</child>
        <parent>wave_glider_umbilical_joint_joint</parent>
        <axis>
          <limit>
            <lower>-0.8</lower>
            <upper>0.8</upper>
          </limit>
          <dynamics>
            <damping>0.1</damping>
          </dynamics>
          <xyz>0 1 0</xyz>
        </axis>
    </joint>

    <link name="wave_glider_sub_body_link">
      <pose>0.23 0 -2.30 0 0 0</pose>
      <inertial>
          <pose>0 0 0 0 0 0</pose>
          <inertia>
              <ixx>0.39815867</ixx>
              <ixy>0</ixy>
              <ixz>0</ixz>
              <iyy>29.511223</iyy>
              <iyz>0</iyz>
              <izz>29.14933567</izz>
          </inertia>
          <mass>84</mass>
      </inertial>
      <collision name="body_collision">
        <geometry>
          <mesh>
            <scale>1.0 1.0 1.0</scale>
            <uri>model://glider_wave/mesh/wave_glider_sub_body_collision_v2.stl</uri>
          </mesh>
        </geometry>
      </collision>
      <visual name="body_visual">
        <geometry>
          <mesh>
            <scale>1.0 1.0 1.0</scale>
            <uri>model://glider_wave/mesh/wave_glider_sub_body_v2.dae</uri>
          </mesh>
        </geometry>
      </visual>
      <!-- leave for debugging rudder position -->
      <visual name="rudder_visual">
        <geometry>
          <mesh>
            <scale>1.0 1.0 1.0</scale>
            <uri>model://glider_wave/mesh/wave_glider_sub_rudder_v2.dae</uri>
          </mesh>
        </geometry>
      </visual>
      <!-- leave for debugging thruster position -->
      <!-- <visual name="thruster_visual">
        <geometry>
          <mesh>
            <scale>1.0 1.0 1.0</scale>
            <uri>model://glider_wave/mesh/wave_glider_sub_thruster_v2.dae</uri>
          </mesh>
        </geometry>
      </visual> -->
      <!-- leave for debugging wing positions -->
      <!-- <visual name="wings_visual">
        <geometry>
          <mesh>
            <scale>1.0 1.0 1.0</scale>
            <uri>model://glider_wave/mesh/wave_glider_sub_wings_v2.dae</uri>
          </mesh>
        </geometry>
      </visual> -->
    </link>
    <joint name="wave_glider_sub_body_joint" type="revolute">
      <pose relative_to="wave_glider_sub_body_link">0 0 0.175 0 0 0</pose>
      <child>wave_glider_sub_body_link</child>
      <parent>wave_glider_umbilical_link</parent>
      <axis>
        <limit>
          <lower>-0.8</lower>
          <upper>0.8</upper>
        </limit>
        <dynamics>
          <damping>0.1</damping>
        </dynamics>
        <xyz>0 1 0</xyz>
      </axis>
    </joint>

    <link name="wave_glider_sub_wing1_link">
      <pose relative_to="wave_glider_sub_body_link">0.59839 0 0.064323 0 0 0</pose>
      <inertial>
          <pose>0 0 0 0 0 0</pose>
          <inertia>
              <ixx>0.172818253</ixx>
              <ixy>0</ixy>
              <ixz>0</ixz>
              <iyy>0.002342337</iyy>
              <iyz>0</iyz>
              <izz>0.175124083</izz>
          </inertia>
          <mass>1</mass>
      </inertial>
      <collision name="wing_collision">
        <geometry>
          <box>
            <size>0.167 1.44 0.0148</size>
          </box>
        </geometry>
      </collision>
      <visual name="wing_visual">
        <geometry>
          <mesh>
            <scale>1.0 1.0 1.0</scale>
            <uri>model://glider_wave/mesh/wave_glider_sub_wing_v2.dae</uri>
          </mesh>
        </geometry>
      </visual>
    </link>
    <joint name="wave_glider_sub_wing1_joint" type="revolute">
      <pose relative_to="wave_glider_sub_body_link">0.64014 0 0.064323 0 0 0</pose>
      <child>wave_glider_sub_wing1_link</child>
      <parent>wave_glider_sub_body_link</parent>
      <axis>
        <limit>
          <lower>-0.8</lower>
          <upper>0.8</upper>
        </limit>
        <dynamics>
          <damping>0.1</damping>
        </dynamics>
        <xyz>0 1 0</xyz>
      </axis>
    </joint>

    <link name="wave_glider_sub_wing2_link">
      <pose relative_to="wave_glider_sub_body_link">0.38399 0 0.064323 0 0 0</pose>
      <inertial>
          <pose>0 0 0 0 0 0</pose>
          <inertia>
              <ixx>0.172818253</ixx>
              <ixy>0</ixy>
              <ixz>0</ixz>
              <iyy>0.002342337</iyy>
              <iyz>0</iyz>
              <izz>0.175124083</izz>
          </inertia>
          <mass>1</mass>
      </inertial>
      <collision name="wing_collision">
        <geometry>
          <box>
            <size>0.167 1.44 0.0148</size>
          </box>
        </geometry>
      </collision>
      <visual name="wing_visual">
        <geometry>
          <mesh>
            <scale>1.0 1.0 1.0</scale>
            <uri>model://glider_wave/mesh/wave_glider_sub_wing_v2.dae</uri>
          </mesh>
        </geometry>
      </visual>
    </link>
    <joint name="wave_glider_sub_wing2_joint" type="revolute">
      <pose relative_to="wave_glider_sub_body_link">0.42574 0 0.064323 0 0 0</pose>
      <child>wave_glider_sub_wing2_link</child>
      <parent>wave_glider_sub_body_link</parent>
      <axis>
        <limit>
          <lower>-0.8</lower>
          <upper>0.8</upper>
        </limit>
        <dynamics>
          <damping>0.1</damping>
        </dynamics>
        <xyz>0 1 0</xyz>
      </axis>
    </joint>

    <link name="wave_glider_sub_wing3_link">
      <pose relative_to="wave_glider_sub_body_link">0.18322 0 0.064323 0 0 0</pose>
      <inertial>
          <pose>0 0 0 0 0 0</pose>
          <inertia>
              <ixx>0.172818253</ixx>
              <ixy>0</ixy>
              <ixz>0</ixz>
              <iyy>0.002342337</iyy>
              <iyz>0</iyz>
              <izz>0.175124083</izz>
          </inertia>
          <mass>1</mass>
      </inertial>
      <collision name="wing_collision">
        <geometry>
          <box>
            <size>0.167 1.44 0.0148</size>
          </box>
        </geometry>
      </collision>
      <visual name="wing_visual">
        <geometry>
          <mesh>
            <scale>1.0 1.0 1.0</scale>
            <uri>model://glider_wave/mesh/wave_glider_sub_wing_v2.dae</uri>
          </mesh>
        </geometry>
      </visual>
    </link>
    <joint name="wave_glider_sub_wing3_joint" type="revolute">
      <pose relative_to="wave_glider_sub_body_link">0.22497 0 0.064323 0 0 0</pose>
      <child>wave_glider_sub_wing3_link</child>
      <parent>wave_glider_sub_body_link</parent>
      <axis>
        <limit>
          <lower>-0.8</lower>
          <upper>0.8</upper>
        </limit>
        <dynamics>
          <damping>0.1</damping>
        </dynamics>
        <xyz>0 1 0</xyz>
      </axis>
    </joint>

    <link name="wave_glider_sub_wing4_link">
      <pose relative_to="wave_glider_sub_body_link">-0.13839 0 0.064323 0 0 0</pose>
      <inertial>
          <pose>0 0 0 0 0 0</pose>
          <inertia>
              <ixx>0.172818253</ixx>
              <ixy>0</ixy>
              <ixz>0</ixz>
              <iyy>0.002342337</iyy>
              <iyz>0</iyz>
              <izz>0.175124083</izz>
          </inertia>
          <mass>1</mass>
      </inertial>
      <collision name="wing_collision">
        <geometry>
          <box>
            <size>0.167 1.44 0.0148</size>
          </box>
        </geometry>
      </collision>
      <visual name="wing_visual">
        <geometry>
          <mesh>
            <scale>1.0 1.0 1.0</scale>
            <uri>model://glider_wave/mesh/wave_glider_sub_wing_v2.dae</uri>
          </mesh>
        </geometry>
      </visual>
    </link>
    <joint name="wave_glider_sub_wing4_joint" type="revolute">
      <pose relative_to="wave_glider_sub_body_link">-0.09664 0 0.064323 0 0 0</pose>
      <child>wave_glider_sub_wing4_link</child>
      <parent>wave_glider_sub_body_link</parent>
      <axis>
        <limit>
          <lower>-0.8</lower>
          <upper>0.8</upper>
        </limit>
        <dynamics>
          <damping>0.1</damping>
        </dynamics>
        <xyz>0 1 0</xyz>
      </axis>
    </joint>

    <link name="wave_glider_sub_wing5_link">
      <pose relative_to="wave_glider_sub_body_link">-0.3528 0 0.064323 0 0 0</pose>
      <inertial>
          <pose>0 0 0 0 0 0</pose>
          <inertia>
              <ixx>0.172818253</ixx>
              <ixy>0</ixy>
              <ixz>0</ixz>
              <iyy>0.002342337</iyy>
              <iyz>0</iyz>
              <izz>0.175124083</izz>
          </inertia>
          <mass>1</mass>
      </inertial>
      <collision name="wing_collision">
        <geometry>
          <box>
            <size>0.167 1.44 0.0148</size>
          </box>
        </geometry>
      </collision>
      <visual name="wing_visual">
        <geometry>
          <mesh>
            <scale>1.0 1.0 1.0</scale>
            <uri>model://glider_wave/mesh/wave_glider_sub_wing_v2.dae</uri>
          </mesh>
        </geometry>
      </visual>
    </link>
    <joint name="wave_glider_sub_wing5_joint" type="revolute">
      <pose relative_to="wave_glider_sub_body_link">-0.31105 0 0.064323 0 0 0</pose>
      <child>wave_glider_sub_wing5_link</child>
      <parent>wave_glider_sub_body_link</parent>
      <axis>
        <limit>
          <lower>-0.8</lower>
          <upper>0.8</upper>
        </limit>
        <dynamics>
          <damping>0.1</damping>
        </dynamics>
        <xyz>0 1 0</xyz>
      </axis>
    </joint>

    <link name="wave_glider_sub_wing6_link">
      <pose relative_to="wave_glider_sub_body_link">-0.56136 0 0.064323 0 0 0</pose>
      <inertial>
          <pose>0 0 0 0 0 0</pose>
          <inertia>
              <ixx>0.172818253</ixx>
              <ixy>0</ixy>
              <ixz>0</ixz>
              <iyy>0.002342337</iyy>
              <iyz>0</iyz>
              <izz>0.175124083</izz>
          </inertia>
          <mass>1</mass>
      </inertial>
      <collision name="wing_collision">
        <geometry>
          <box>
            <size>0.167 1.44 0.0148</size>
          </box>
        </geometry>
      </collision>
      <visual name="wing_visual">
        <geometry>
          <mesh>
            <scale>1.0 1.0 1.0</scale>
            <uri>model://glider_wave/mesh/wave_glider_sub_wing_v2.dae</uri>
          </mesh>
        </geometry>
      </visual>
    </link>
    <joint name="wave_glider_sub_wing6_joint" type="revolute">
      <pose relative_to="wave_glider_sub_body_link">-0.51961 0 0.064323 0 0 0</pose>
      <child>wave_glider_sub_wing6_link</child>
      <parent>wave_glider_sub_body_link</parent>
      <axis>
        <limit>
          <lower>-0.8</lower>
          <upper>0.8</upper>
        </limit>
        <dynamics>
          <damping>0.1</damping>
        </dynamics>
        <xyz>0 1 0</xyz>
      </axis>
    </joint>

    <link name="wave_glider_sub_thruster_link">
      <pose relative_to="wave_glider_sub_body_link" degrees="true">-0.856622 0 0 0 -90 0</pose>
      <inertial>
          <pose>0 0 0 0 0 0</pose>
          <inertia>
              <ixx>0.013428506</ixx>
              <ixy>0</ixy>
              <ixz>0</ixz>
              <iyy>0.013428506</iyy>
              <iyz>0</iyz>
              <izz>0.000852845</izz>
          </inertia>
          <mass>1</mass>
      </inertial>
      <collision name="thruster_collision">
        <pose>0 0 0.1975 0 0 0</pose>
        <geometry>
          <cylinder>
            <radius>0.0413</radius>
            <length>0.395</length>
          </cylinder>
        </geometry>
      </collision>
      <visual name="thruster_visual">
        <geometry>
          <mesh>
            <scale>1.0 1.0 1.0</scale>
            <uri>model://glider_wave/mesh/wave_glider_sub_thruster_v3.dae</uri>
          </mesh>
        </geometry>
      </visual>
    </link>
    <joint name="wave_glider_sub_thruster_joint" type="revolute">
      <pose relative_to="wave_glider_sub_body_link" degrees="true">-0.856622 0 0 0 -90 0</pose>
      <child>wave_glider_sub_thruster_link</child>
      <parent>wave_glider_sub_body_link</parent>
      <axis>
        <limit>
          <lower>-1.0E-16</lower>
          <upper>1.0E+16</upper>
        </limit>
        <dynamics>
          <damping>0.01</damping>
        </dynamics>
        <xyz>0 0 1</xyz>
      </axis>
    </joint>



    <!-- Hydrodynamics plugin -->
    <plugin
        filename="gz-waves1-hydrodynamics-system"  
        name="gz::sim::systems::Hydrodynamics">
      
        <enable>wave_glider::wave_glider_float_link</enable>
        <enable>wave_glider::wave_glider_sub_body_link</enable>
        <enable>wave_glider::wave_glider_sub_wing1_link</enable>
        <enable>wave_glider::wave_glider_sub_wing2_link</enable>
        <enable>wave_glider::wave_glider_sub_wing3_link</enable>
        <enable>wave_glider::wave_glider_sub_wing4_link</enable>
        <enable>wave_glider::wave_glider_sub_wing5_link</enable>
        <enable>wave_glider::wave_glider_sub_wing6_link</enable>
          
        <hydrodynamics>
          <!-- <damping_on>1</damping_on>
          <viscous_drag_on>1</viscous_drag_on> 
          <pressure_drag_on>1</pressure_drag_on> -->
        
          <!-- Linear and Angular Damping -->
          <!-- <cDampL1>1.0E-6</cDampL1>
          <cDampL2>1.0E-6</cDampL2>
          <cDampR1>1.0E-6</cDampR1>
          <cDampR2>1.0E-6</cDampR2> -->
    
          <!-- 'Pressure' Drag -->
          <!-- <cPDrag1>1.0E+2</cPDrag1> 
          <cPDrag2>1.0E+2</cPDrag2>
          <fPDrag>0.4</fPDrag>
          <cSDrag1>1.0E+2</cSDrag1>
          <cSDrag2>1.0E+2</cSDrag2>
          <fSDrag>0.4</fSDrag>
          <vRDrag>1.0</vRDrag> -->
        </hydrodynamics>
      </plugin>

  </model>
</sdf>
