<?xml version="1.0"?>

<!--

Rudder position control

  gz topic -t "/rudder_joint/cmd_pos" -m gz.msgs.Double -p "data: 0.5"
  
-->

<sdf version="1.9">
  <model name="wave_glider">

    <link name="wave_glider_float_link">
      <inertial>
        <pose>0 0 -0.13 0 0 0</pose>
          <mass>71</mass>
          <inertia>
            <ixx>4.194916667</ixx>
            <ixy>0</ixy>
            <ixz>0</ixz>
            <iyy>55.35278333</iyy>
            <iyz>0</iyz>
            <izz>58.92171667</izz>
          </inertia>
      </inertial>
      <collision name="collision">
        <geometry>
          <mesh>
            <scale>1.0 1.0 1.0</scale>
            <uri>model://glider_wave/mesh/wave_glider_hull_collision.stl</uri>
          </mesh>
          <!-- <box>
            <size>3.05 0.81 0.23</size>
          </box> -->
        </geometry>
      </collision>
      <collision name="fin_collision">
        <geometry>
          <mesh>
            <scale>1.0 1.0 1.0</scale>
            <uri>model://glider_wave/mesh/wave_glider_fin_collision.stl</uri>
          </mesh>
        </geometry>
      </collision>
      <visual name="visual">
        <pose>0 0 0 0 0 0</pose>
        <geometry>
          <mesh>
            <scale>1.0 1.0 1.0</scale>
            <uri>model://glider_wave/mesh/wave_glider_hull.dae</uri>
          </mesh>
          <!-- <box>
            <size>3.05 0.81 0.23</size>
          </box> -->
        </geometry>
      </visual>
      <visual name="fin_visual">
        <pose>0 0 0 0 0 0</pose>
        <geometry>
          <mesh>
            <scale>1.0 1.0 1.0</scale>
            <uri>model://glider_wave/mesh/wave_glider_fin.dae</uri>
          </mesh>
        </geometry>
      </visual>
      <visual name="sensors_visual">
        <geometry>
          <mesh>
            <scale>1.0 1.0 1.0</scale>
            <uri>model://glider_wave/mesh/wave_glider_sensors.dae</uri>
          </mesh>
        </geometry>
      </visual>
      <visual name="umbilical_connection_visual">
        <geometry>
          <mesh>
            <scale>1.0 1.0 1.0</scale>
            <uri>model://glider_wave/mesh/wave_glider_umbilical_connection.dae</uri>
          </mesh>
        </geometry>
      </visual>
      <!-- leave for debugging centre of pressure -->
      <visual name="cp_fin_visual">
        <pose>-1.195 0 -0.357 0 0 0</pose>
        <geometry>
          <sphere>
            <radius>0.025</radius>
          </sphere>
        </geometry>
        <material>
          <ambient>1 0 0 1</ambient>
          <diffuse>1 0 0 1</diffuse>
          <specular>0.1 0.1 0.1 1</specular>
        </material>
      </visual>
    </link>

    <link name="wave_glider_umbilical_joint_link">
      <inertial>
        <pose>0.23 0 -0.38 0 0 0</pose>
        <mass>0.5</mass>
        <inertia>
          <ixx>0.001</ixx>
          <ixy>0</ixy>
          <ixz>0</ixz>
          <iyy>0.001</iyy>
          <iyz>0</iyz>
          <izz>0.001</izz>
        </inertia>
      </inertial>
      <collision name="collision">
        <geometry>
          <box>
            <size>0.2 0.2 0.2</size>
          </box>
        </geometry>
      </collision>
      <visual name="visual">
        <geometry>
          <mesh>
            <scale>1.0 1.0 1.0</scale>
            <uri>model://glider_wave/mesh/wave_glider_umbilical_joint.dae</uri>
          </mesh>
        </geometry>
      </visual>
    </link>
    <joint name="wave_glider_umbilical_joint_joint" type="revolute">
        <pose>0.23 0 -0.38 0 0 0</pose>
        <child>wave_glider_umbilical_joint_link</child>
        <parent>wave_glider_float_link</parent>
        <axis>
          <limit>
            <lower>-0.8</lower>
            <upper>0.8</upper>
          </limit>
          <dynamics>
            <damping>0.1</damping>
          </dynamics>
          <xyz>1 0 0</xyz>
        </axis>
    </joint>

    <link name="wave_glider_umbilical1_link">
      <pose>0.23 0 -1.31 0 0 0</pose>
      <inertial>
          <mass>1</mass>
          <inertia>
            <ixx>0.240989583</ixx>
            <ixy>0</ixy>
            <ixz>0</ixz>
            <iyy>0.240989583</iyy>
            <iyz>0</iyz>
            <izz>0.0003125</izz>
          </inertia>
      </inertial>
      <collision name="collision">
        <geometry>
          <cylinder>
            <radius>0.024</radius>
            <length>1.7</length>
          </cylinder>
        </geometry>
      </collision>
      <visual name="visual">
        <!-- <pose>-0.23 0 1.31 0 0 0</pose> -->
        <geometry>
          <!-- <mesh>
            <scale>1.0 1.0 1.0</scale>
            <uri>model://glider_wave/mesh/wave_glider_umbilical.dae</uri>
          </mesh> -->
          <cylinder>
            <radius>0.024</radius>
            <length>1.7</length>
          </cylinder>
        </geometry>
      </visual>
    </link>  
    <joint name="wave_glider_umbilical1_joint" type="revolute">
        <pose>0 0 0.85 0 0 0</pose>
        <child>wave_glider_umbilical1_link</child>
        <parent>wave_glider_umbilical_joint_joint</parent>
        <axis>
          <limit>
            <lower>-0.8</lower>
            <upper>0.8</upper>
          </limit>
          <dynamics>
            <damping>0.5</damping>
          </dynamics>
          <xyz>0 1 0</xyz>
        </axis>
    </joint>

    <link name="wave_glider_spring1_link">
      <pose relative_to="wave_glider_umbilical1_link">0 0 -0.85 0 0 0</pose>
      <inertial>
          <mass>0.1</mass>
          <inertia>
            <ixx>0.001</ixx>
            <ixy>0</ixy>
            <ixz>0</ixz>
            <iyy>0.001</iyy>
            <iyz>0</iyz>
            <izz>0.001</izz>
          </inertia>
      </inertial>
      <collision name="collision">
        <geometry>
          <cylinder>
            <radius>0.024</radius>
            <length>0.01</length>
          </cylinder>
        </geometry>
      </collision>
      <visual name="visual">
        <geometry>
          <cylinder>
            <radius>0.024</radius>
            <length>0.01</length>
          </cylinder>
        </geometry>
      </visual>
    </link>
    <joint name="wave_glider_spring1_joint" type="prismatic">
        <pose>0 0 0 0 0 0</pose>
        <child>wave_glider_spring1_link</child>
        <parent>wave_glider_umbilical1_link</parent>
        <axis>
          <limit>
            <lower>-0.25</lower>
            <upper>0.25</upper>
          </limit>
          <dynamics>
            <damping>0.01</damping>
            <spring_stiffness>1</spring_stiffness>
          </dynamics>
          <xyz>0 0 1</xyz>
        </axis>
    </joint>

    <link name="wave_glider_umbilical2_link">
      <pose relative_to="wave_glider_umbilical1_link">0 0 -1.7 0 0 0</pose>
      <inertial>
          <mass>1</mass>
          <inertia>
            <ixx>0.240989583</ixx>
            <ixy>0</ixy>
            <ixz>0</ixz>
            <iyy>0.240989583</iyy>
            <iyz>0</iyz>
            <izz>0.0003125</izz>
          </inertia>
      </inertial>
      <collision name="collision">
        <geometry>
          <cylinder>
            <radius>0.024</radius>
            <length>1.7</length>
          </cylinder>
        </geometry>
      </collision>
      <visual name="visual">
        <geometry>
          <cylinder>
            <radius>0.024</radius>
            <length>1.7</length>
          </cylinder>
        </geometry>
      </visual>
    </link>
    <joint name="wave_glider_umbilical2_joint" type="revolute">
        <pose>0 0 0.85 0 0 0</pose>
        <child>wave_glider_umbilical2_link</child>
        <parent>wave_glider_spring1_link</parent>
        <axis>
          <limit>
            <lower>-0.8</lower>
            <upper>0.8</upper>
          </limit>
          <dynamics>
            <damping>0.5</damping>
          </dynamics>
          <xyz>0 1 0</xyz>
        </axis>
    </joint>

    <link name="wave_glider_spring2_link">
      <pose relative_to="wave_glider_umbilical2_link">0 0 -0.85 0 0 0</pose>
      <inertial>
          <mass>0.1</mass>
          <inertia>
            <ixx>0.001</ixx>
            <ixy>0</ixy>
            <ixz>0</ixz>
            <iyy>0.001</iyy>
            <iyz>0</iyz>
            <izz>0.001</izz>
          </inertia>
      </inertial>
      <collision name="collision">
        <geometry>
          <cylinder>
            <radius>0.024</radius>
            <length>0.01</length>
          </cylinder>
        </geometry>
      </collision>
      <visual name="visual">
        <geometry>
          <cylinder>
            <radius>0.024</radius>
            <length>0.01</length>
          </cylinder>
        </geometry>
      </visual>
    </link>
    <joint name="wave_glider_spring2_joint" type="prismatic">
        <pose>0 0 0 0 0 0</pose>
        <child>wave_glider_spring2_link</child>
        <parent>wave_glider_umbilical2_link</parent>
        <axis>
          <limit>
            <lower>-0.25</lower>
            <upper>0.25</upper>
          </limit>
          <dynamics>
            <damping>0.01</damping>
            <spring_stiffness>1</spring_stiffness>
          </dynamics>
          <xyz>0 0 1</xyz>
        </axis>
    </joint>

    <link name="wave_glider_umbilical3_link">
      <pose relative_to="wave_glider_umbilical2_link">0 0 -1.7 0 0 0</pose>
      <inertial>
          <mass>1</mass>
          <inertia>
            <ixx>0.240989583</ixx>
            <ixy>0</ixy>
            <ixz>0</ixz>
            <iyy>0.240989583</iyy>
            <iyz>0</iyz>
            <izz>0.0003125</izz>
          </inertia>
      </inertial>
      <collision name="collision">
        <geometry>
          <cylinder>
            <radius>0.024</radius>
            <length>1.7</length>
          </cylinder>
        </geometry>
      </collision>
      <visual name="visual">
        <geometry>
          <cylinder>
            <radius>0.024</radius>
            <length>1.7</length>
          </cylinder>
        </geometry>
      </visual>
    </link>
    <joint name="wave_glider_umbilical3_joint" type="revolute">
        <pose>0 0 0.85 0 0 0</pose>
        <child>wave_glider_umbilical3_link</child>
        <parent>wave_glider_spring2_link</parent>
        <axis>
          <limit>
            <lower>-0.8</lower>
            <upper>0.8</upper>
          </limit>
          <dynamics>
            <damping>0.5</damping>
          </dynamics>
          <xyz>0 1 0</xyz>
        </axis>
    </joint>

    <link name="wave_glider_spring3_link">
      <pose relative_to="wave_glider_umbilical3_link">0 0 -0.85 0 0 0</pose>
      <inertial>
          <mass>0.1</mass>
          <inertia>
            <ixx>0.001</ixx>
            <ixy>0</ixy>
            <ixz>0</ixz>
            <iyy>0.001</iyy>
            <iyz>0</iyz>
            <izz>0.001</izz>
          </inertia>
      </inertial>
      <collision name="collision">
        <geometry>
          <cylinder>
            <radius>0.024</radius>
            <length>0.01</length>
          </cylinder>
        </geometry>
      </collision>
      <visual name="visual">
        <geometry>
          <cylinder>
            <radius>0.024</radius>
            <length>0.01</length>
          </cylinder>
        </geometry>
      </visual>
    </link>
    <joint name="wave_glider_spring3_joint" type="prismatic">
        <pose>0 0 0 0 0 0</pose>
        <child>wave_glider_spring3_link</child>
        <parent>wave_glider_umbilical3_link</parent>
        <axis>
          <limit>
            <lower>-0.25</lower>
            <upper>0.25</upper>
          </limit>
          <dynamics>
            <damping>0.01</damping>
            <spring_stiffness>1</spring_stiffness>
          </dynamics>
          <xyz>0 0 1</xyz>
        </axis>
    </joint>

    <link name="wave_glider_umbilical4_link">
      <pose relative_to="wave_glider_umbilical3_link">0 0 -1.7 0 0 0</pose>
      <inertial>
          <mass>1</mass>
          <inertia>
            <ixx>0.240989583</ixx>
            <ixy>0</ixy>
            <ixz>0</ixz>
            <iyy>0.240989583</iyy>
            <iyz>0</iyz>
            <izz>0.0003125</izz>
          </inertia>
      </inertial>
      <collision name="collision">
        <geometry>
          <cylinder>
            <radius>0.024</radius>
            <length>1.7</length>
          </cylinder>
        </geometry>
      </collision>
      <visual name="visual">
        <geometry>
          <cylinder>
            <radius>0.024</radius>
            <length>1.7</length>
          </cylinder>
        </geometry>
      </visual>
    </link>
    <joint name="wave_glider_umbilical4_joint" type="revolute">
        <pose>0 0 0.85 0 0 0</pose>
        <child>wave_glider_umbilical4_link</child>
        <parent>wave_glider_spring3_link</parent>
        <axis>
          <limit>
            <lower>-0.8</lower>
            <upper>0.8</upper>
          </limit>
          <dynamics>
            <damping>0.5</damping>
          </dynamics>
          <xyz>0 1 0</xyz>
        </axis>
    </joint>

    <link name="wave_glider_sub_body_link">
      <pose relative_to="wave_glider_umbilical4_link">0 0 -1.025 0 0 0</pose>
      <inertial>
          <pose>0.03 0 0 0 0 0</pose>
          <mass>56</mass>
          <inertia>
              <ixx>0.255959145</ixx>
              <ixy>0</ixy>
              <ixz>0</ixz>
              <iyy>18.9715005</iyy>
              <iyz>0</iyz>
              <izz>18.73885865</izz>
          </inertia>
      </inertial>
      <collision name="body_collision">
        <geometry>
          <mesh>
            <scale>1.0 1.0 1.0</scale>
            <uri>model://glider_wave/mesh/wave_glider_sub_body_collision_v2.stl</uri>
          </mesh>
        </geometry>
      </collision>
      <visual name="body_visual">
        <geometry>
          <mesh>
            <scale>1.0 1.0 1.0</scale>
            <uri>model://glider_wave/mesh/wave_glider_sub_body_v2.dae</uri>
          </mesh>
        </geometry>
      </visual>
      <!-- leave for debugging rudder position -->
      <!-- <visual name="rudder_visual">
        <geometry>
          <mesh>
            <scale>1.0 1.0 1.0</scale>
            <uri>model://glider_wave/mesh/wave_glider_sub_rudder_v2.dae</uri>
          </mesh>
        </geometry>
      </visual> -->
      <!-- leave for debugging thruster position -->
      <!-- <visual name="thruster_visual">
        <geometry>
          <mesh>
            <scale>1.0 1.0 1.0</scale>
            <uri>model://glider_wave/mesh/wave_glider_sub_thruster_v2.dae</uri>
          </mesh>
        </geometry>
      </visual> -->
      <!-- leave for debugging wing positions -->
      <!-- <visual name="wings_visual">
        <geometry>
          <mesh>
            <scale>1.0 1.0 1.0</scale>
            <uri>model://glider_wave/mesh/wave_glider_sub_wings_v2.dae</uri>
          </mesh>
        </geometry>
      </visual> -->
    </link>
    <joint name="wave_glider_sub_body_joint" type="revolute">
      <!-- <pose relative_to="wave_glider_sub_body_link">0 0 0.175 0 0 0</pose> -->
      <pose>0 0 0.175 0 0 0</pose>
      <child>wave_glider_sub_body_link</child>
      <parent>wave_glider_umbilical4_link</parent>
      <axis>
        <limit>
          <lower>-0.8</lower>
          <upper>0.8</upper>
        </limit>
        <dynamics>
          <damping>0.1</damping>
        </dynamics>
        <xyz>0 1 0</xyz>
      </axis>
    </joint>

    <link name="wave_glider_sub_wing1_link">
      <pose relative_to="wave_glider_sub_body_link">0.59839 0 0.064323 0 0 0</pose>
      <inertial>
          <pose>0 0 0 0 0 0</pose>
          <mass>4</mass>
          <inertia>
              <ixx>0.691273013</ixx>
              <ixy>0</ixy>
              <ixz>0</ixz>
              <iyy>0.009369347</iyy>
              <iyz>0</iyz>
              <izz>0.700496333</izz>
          </inertia>
      </inertial>
      <collision name="wing_collision">
        <geometry>
          <box>
            <size>0.167 1.44 0.0148</size>
          </box>
        </geometry>
      </collision>
      <visual name="wing_visual">
        <geometry>
          <mesh>
            <scale>1.0 1.0 1.0</scale>
            <uri>model://glider_wave/mesh/wave_glider_sub_wing_v2.dae</uri>
          </mesh>
        </geometry>
      </visual>
      <!-- leave for debugging centre of pressure -->
      <visual name="cp_wing_visual">
        <pose>0.04175 0 0 0 0 0</pose>
        <geometry>
          <sphere>
            <radius>0.025</radius>
          </sphere>
        </geometry>
        <material>
          <ambient>1 0 0 1</ambient>
          <diffuse>1 0 0 1</diffuse>
          <specular>0.1 0.1 0.1 1</specular>
        </material>
      </visual>
    </link>
    <joint name="wave_glider_sub_wing1_joint" type="revolute">
      <pose relative_to="wave_glider_sub_body_link">0.64014 0 0.064323 0 0 0</pose>
      <child>wave_glider_sub_wing1_link</child>
      <parent>wave_glider_sub_body_link</parent>
      <axis>
        <limit>
          <lower>-0.8</lower>
          <upper>0.8</upper>
        </limit>
        <dynamics>
          <damping>0.01</damping>
        </dynamics>
        <xyz>0 1 0</xyz>
      </axis>
    </joint>

    <link name="wave_glider_sub_wing2_link">
      <pose relative_to="wave_glider_sub_body_link">0.38399 0 0.064323 0 0 0</pose>
      <inertial>
          <pose>0 0 0 0 0 0</pose>
          <mass>4</mass>
          <inertia>
              <ixx>0.691273013</ixx>
              <ixy>0</ixy>
              <ixz>0</ixz>
              <iyy>0.009369347</iyy>
              <iyz>0</iyz>
              <izz>0.700496333</izz>
          </inertia>
      </inertial>
      <collision name="wing_collision">
        <geometry>
          <box>
            <size>0.167 1.44 0.0148</size>
          </box>
        </geometry>
      </collision>
      <visual name="wing_visual">
        <geometry>
          <mesh>
            <scale>1.0 1.0 1.0</scale>
            <uri>model://glider_wave/mesh/wave_glider_sub_wing_v2.dae</uri>
          </mesh>
        </geometry>
      </visual>
      <!-- leave for debugging centre of pressure -->
      <visual name="cp_wing_visual">
        <pose>0.04175 0 0 0 0 0</pose>
        <geometry>
          <sphere>
            <radius>0.025</radius>
          </sphere>
        </geometry>
        <material>
          <ambient>1 0 0 1</ambient>
          <diffuse>1 0 0 1</diffuse>
          <specular>0.1 0.1 0.1 1</specular>
        </material>
      </visual>
    </link>
    <joint name="wave_glider_sub_wing2_joint" type="revolute">
      <pose relative_to="wave_glider_sub_body_link">0.42574 0 0.064323 0 0 0</pose>
      <child>wave_glider_sub_wing2_link</child>
      <parent>wave_glider_sub_body_link</parent>
      <axis>
        <limit>
          <lower>-0.8</lower>
          <upper>0.8</upper>
        </limit>
        <dynamics>
          <damping>0.01</damping>
        </dynamics>
        <xyz>0 1 0</xyz>
      </axis>
    </joint>

    <link name="wave_glider_sub_wing3_link">
      <pose relative_to="wave_glider_sub_body_link">0.18322 0 0.064323 0 0 0</pose>
      <inertial>
          <pose>0 0 0 0 0 0</pose>
          <mass>4</mass>
          <inertia>
              <ixx>0.691273013</ixx>
              <ixy>0</ixy>
              <ixz>0</ixz>
              <iyy>0.009369347</iyy>
              <iyz>0</iyz>
              <izz>0.700496333</izz>
          </inertia>
      </inertial>
      <collision name="wing_collision">
        <geometry>
          <box>
            <size>0.167 1.44 0.0148</size>
          </box>
        </geometry>
      </collision>
      <visual name="wing_visual">
        <geometry>
          <mesh>
            <scale>1.0 1.0 1.0</scale>
            <uri>model://glider_wave/mesh/wave_glider_sub_wing_v2.dae</uri>
          </mesh>
        </geometry>
      </visual>
      <!-- leave for debugging centre of pressure -->
      <visual name="cp_wing_visual">
        <pose>0.04175 0 0 0 0 0</pose>
        <geometry>
          <sphere>
            <radius>0.025</radius>
          </sphere>
        </geometry>
        <material>
          <ambient>1 0 0 1</ambient>
          <diffuse>1 0 0 1</diffuse>
          <specular>0.1 0.1 0.1 1</specular>
        </material>
      </visual>
    </link>
    <joint name="wave_glider_sub_wing3_joint" type="revolute">
      <pose relative_to="wave_glider_sub_body_link">0.22497 0 0.064323 0 0 0</pose>
      <child>wave_glider_sub_wing3_link</child>
      <parent>wave_glider_sub_body_link</parent>
      <axis>
        <limit>
          <lower>-0.8</lower>
          <upper>0.8</upper>
        </limit>
        <dynamics>
          <damping>0.01</damping>
        </dynamics>
        <xyz>0 1 0</xyz>
      </axis>
    </joint>

    <link name="wave_glider_sub_wing4_link">
      <pose relative_to="wave_glider_sub_body_link">-0.13839 0 0.064323 0 0 0</pose>
      <inertial>
          <pose>0 0 0 0 0 0</pose>
          <mass>4</mass>
          <inertia>
              <ixx>0.691273013</ixx>
              <ixy>0</ixy>
              <ixz>0</ixz>
              <iyy>0.009369347</iyy>
              <iyz>0</iyz>
              <izz>0.700496333</izz>
          </inertia>
      </inertial>
      <collision name="wing_collision">
        <geometry>
          <box>
            <size>0.167 1.44 0.0148</size>
          </box>
        </geometry>
      </collision>
      <visual name="wing_visual">
        <geometry>
          <mesh>
            <scale>1.0 1.0 1.0</scale>
            <uri>model://glider_wave/mesh/wave_glider_sub_wing_v2.dae</uri>
          </mesh>
        </geometry>
      </visual>
      <!-- leave for debugging centre of pressure -->
      <visual name="cp_wing_visual">
        <pose>0.04175 0 0 0 0 0</pose>
        <geometry>
          <sphere>
            <radius>0.025</radius>
          </sphere>
        </geometry>
        <material>
          <ambient>1 0 0 1</ambient>
          <diffuse>1 0 0 1</diffuse>
          <specular>0.1 0.1 0.1 1</specular>
        </material>
      </visual>
    </link>
    <joint name="wave_glider_sub_wing4_joint" type="revolute">
      <pose relative_to="wave_glider_sub_body_link">-0.09664 0 0.064323 0 0 0</pose>
      <child>wave_glider_sub_wing4_link</child>
      <parent>wave_glider_sub_body_link</parent>
      <axis>
        <limit>
          <lower>-0.8</lower>
          <upper>0.8</upper>
        </limit>
        <dynamics>
          <damping>0.01</damping>
        </dynamics>
        <xyz>0 1 0</xyz>
      </axis>
    </joint>

    <link name="wave_glider_sub_wing5_link">
      <pose relative_to="wave_glider_sub_body_link">-0.3528 0 0.064323 0 0 0</pose>
      <inertial>
          <pose>0 0 0 0 0 0</pose>
          <mass>4</mass>
          <inertia>
              <ixx>0.691273013</ixx>
              <ixy>0</ixy>
              <ixz>0</ixz>
              <iyy>0.009369347</iyy>
              <iyz>0</iyz>
              <izz>0.700496333</izz>
          </inertia>
      </inertial>
      <collision name="wing_collision">
        <geometry>
          <box>
            <size>0.167 1.44 0.0148</size>
          </box>
        </geometry>
      </collision>
      <visual name="wing_visual">
        <geometry>
          <mesh>
            <scale>1.0 1.0 1.0</scale>
            <uri>model://glider_wave/mesh/wave_glider_sub_wing_v2.dae</uri>
          </mesh>
        </geometry>
      </visual>
      <!-- leave for debugging centre of pressure -->
      <visual name="cp_wing_visual">
        <pose>0.04175 0 0 0 0 0</pose>
        <geometry>
          <sphere>
            <radius>0.025</radius>
          </sphere>
        </geometry>
        <material>
          <ambient>1 0 0 1</ambient>
          <diffuse>1 0 0 1</diffuse>
          <specular>0.1 0.1 0.1 1</specular>
        </material>
      </visual>
    </link>
    <joint name="wave_glider_sub_wing5_joint" type="revolute">
      <pose relative_to="wave_glider_sub_body_link">-0.31105 0 0.064323 0 0 0</pose>
      <child>wave_glider_sub_wing5_link</child>
      <parent>wave_glider_sub_body_link</parent>
      <axis>
        <limit>
          <lower>-0.8</lower>
          <upper>0.8</upper>
        </limit>
        <dynamics>
          <damping>0.01</damping>
        </dynamics>
        <xyz>0 1 0</xyz>
      </axis>
    </joint>

    <link name="wave_glider_sub_wing6_link">
      <pose relative_to="wave_glider_sub_body_link">-0.56136 0 0.064323 0 0 0</pose>
      <inertial>
          <pose>0 0 0 0 0 0</pose>
          <mass>4</mass>
          <inertia>
              <ixx>0.691273013</ixx>
              <ixy>0</ixy>
              <ixz>0</ixz>
              <iyy>0.009369347</iyy>
              <iyz>0</iyz>
              <izz>0.700496333</izz>
          </inertia>
      </inertial>
      <collision name="wing_collision">
        <geometry>
          <box>
            <size>0.167 1.44 0.0148</size>
          </box>
        </geometry>
      </collision>
      <visual name="wing_visual">
        <geometry>
          <mesh>
            <scale>1.0 1.0 1.0</scale>
            <uri>model://glider_wave/mesh/wave_glider_sub_wing_v2.dae</uri>
          </mesh>
        </geometry>
      </visual>
      <!-- leave for debugging centre of pressure -->
      <visual name="cp_wing_visual">
        <pose>0.04175 0 0 0 0 0</pose>
        <geometry>
          <sphere>
            <radius>0.025</radius>
          </sphere>
        </geometry>
        <material>
          <ambient>1 0 0 1</ambient>
          <diffuse>1 0 0 1</diffuse>
          <specular>0.1 0.1 0.1 1</specular>
        </material>
      </visual>
    </link>
    <joint name="wave_glider_sub_wing6_joint" type="revolute">
      <pose relative_to="wave_glider_sub_body_link">-0.51961 0 0.064323 0 0 0</pose>
      <child>wave_glider_sub_wing6_link</child>
      <parent>wave_glider_sub_body_link</parent>
      <axis>
        <limit>
          <lower>-0.8</lower>
          <upper>0.8</upper>
        </limit>
        <dynamics>
          <damping>0.01</damping>
        </dynamics>
        <xyz>0 1 0</xyz>
      </axis>
    </joint>

    <link name="wave_glider_sub_thruster_link">
      <pose relative_to="wave_glider_sub_body_link" degrees="true">-0.856622 0 0 0 -90 0</pose>
      <inertial>
          <pose>0 0 0.1975 0 0 0</pose>
          <mass>1</mass>
          <inertia>
              <ixx>0.013428506</ixx>
              <ixy>0</ixy>
              <ixz>0</ixz>
              <iyy>0.013428506</iyy>
              <iyz>0</iyz>
              <izz>0.000852845</izz>
          </inertia>
      </inertial>
      <collision name="thruster_collision">
        <pose>0 0 0.1975 0 0 0</pose>
        <geometry>
          <cylinder>
            <radius>0.0413</radius>
            <length>0.395</length>
          </cylinder>
        </geometry>
      </collision>
      <visual name="thruster_visual">
        <geometry>
          <mesh>
            <scale>1.0 1.0 1.0</scale>
            <uri>model://glider_wave/mesh/wave_glider_sub_thruster_v3.dae</uri>
          </mesh>
        </geometry>
      </visual>
    </link>
    <joint name="wave_glider_sub_thruster_joint" type="revolute">
      <pose relative_to="wave_glider_sub_body_link" degrees="true">-0.856622 0 0 0 -90 0</pose>
      <child>wave_glider_sub_thruster_link</child>
      <parent>wave_glider_sub_body_link</parent>
      <axis>
        <limit>
          <lower>-1.0E-16</lower>
          <upper>1.0E+16</upper>
        </limit>
        <dynamics>
          <damping>0.01</damping>
        </dynamics>
        <xyz>0 0 1</xyz>
      </axis>
    </joint>

    <link name="wave_glider_sub_rudder_link">
      <pose relative_to="wave_glider_sub_body_link" degrees="true">-0.99 0 -0.0785 0 8.65 0</pose>
      <inertial>
          <pose>0 0 -0.05375 0 0 0</pose>
          <mass>1</mass>
          <inertia>
              <ixx>0.003855063</ixx>
              <ixy>0</ixy>
              <ixz>0</ixz>
              <iyy>0.006462833</iyy>
              <iyz>0</iyz>
              <izz>0.00261373</izz>
          </inertia>
      </inertial>
      <collision name="rudder_collision">
        <geometry>
          <mesh>
            <scale>1.0 1.0 1.0</scale>
            <uri>model://glider_wave/mesh/wave_glider_sub_rudder_collision_v3.stl</uri>
          </mesh>
        </geometry>
      </collision>
      <visual name="rudder_visual">
        <geometry>
          <mesh>
            <scale>1.0 1.0 1.0</scale>
            <uri>model://glider_wave/mesh/wave_glider_sub_rudder_v3.dae</uri>
          </mesh>
        </geometry>
      </visual>
      <!-- leave for debugging centre of pressure -->
      <visual name="cp_rudder_visual">
        <pose>0 0 -0.062 0 0 0</pose>
        <geometry>
          <sphere>
            <radius>0.025</radius>
          </sphere>
        </geometry>
        <material>
          <ambient>1 0 0 1</ambient>
          <diffuse>1 0 0 1</diffuse>
          <specular>0.1 0.1 0.1 1</specular>
        </material>
      </visual>
    </link>
    <joint name="wave_glider_sub_rudder_joint" type="revolute">
      <pose relative_to="wave_glider_sub_rudder_link" degrees="true">0 0 0 0 0 0</pose>
      <child>wave_glider_sub_rudder_link</child>
      <parent>wave_glider_sub_body_link</parent>
      <axis>
        <limit>
          <lower>-0.8</lower>
          <upper>0.8</upper>
        </limit>
        <dynamics>
          <damping>0.01</damping>
        </dynamics>
        <xyz>0 0 1</xyz>
      </axis>
    </joint>

    <!-- Joint state and force plugins -->
    <plugin filename="gz-sim-joint-state-publisher-system"
      name="gz::sim::systems::JointStatePublisher">
    </plugin>

    <plugin filename="gz-sim-joint-position-controller-system"
        name="gz::sim::systems::JointPositionController">
      <joint_name>wave_glider_sub_rudder_joint</joint_name>
      <topic>/rudder_joint/cmd_pos</topic>
      <p_gain>40</p_gain>
      <i_gain>0.0</i_gain>
      <d_gain>0.1</d_gain>
      <i_max>1</i_max>
      <i_min>-1</i_min>
      <cmd_max>50</cmd_max>
      <cmd_min>-50</cmd_min>
    </plugin>

    <plugin name="gz::sim::systems::FoilLiftDrag"
        filename="asv_sim2-foil-lift-drag-system">
      <a0>0.0</a0>
      <cla>6.2832</cla>
      <alpha_stall>0.1592</alpha_stall>
      <cla_stall>-0.7083</cla_stall>
      <cda>0.63662</cda>
      <area>0.092</area>
      <fluid_density>1000</fluid_density>
      <forward>1 0 0</forward>
      <upward>0 1 0</upward>
      <cp>-1.195 0 -0.357</cp>
      <link_name>wave_glider_float_link</link_name>
      <radial_symmetry>1</radial_symmetry>
      <topic>lift_drag</topic>
    </plugin>

    <plugin name="gz::sim::systems::FoilLiftDrag"
        filename="asv_sim2-foil-lift-drag-system">
      <a0>0.0</a0>
      <cla>6.2832</cla>
      <alpha_stall>0.1592</alpha_stall>
      <cla_stall>-0.7083</cla_stall>
      <cda>0.63662</cda>
      <area>0.02</area>
      <fluid_density>1000</fluid_density>
      <forward>1 0 0</forward>
      <upward>0 1 0</upward>
      <cp>0 0 -0.062</cp>
      <link_name>wave_glider_sub_rudder_link</link_name>
      <radial_symmetry>1</radial_symmetry>
      <topic>lift_drag</topic>
    </plugin>

    <plugin name="gz::sim::systems::FoilLiftDrag"
        filename="asv_sim2-foil-lift-drag-system">
      <a0>0.0</a0>
      <cla>6.2832</cla>
      <alpha_stall>0.1592</alpha_stall>
      <cla_stall>-0.7083</cla_stall>
      <cda>0.63662</cda>
      <area>0.24</area>
      <fluid_density>1000</fluid_density>
      <forward>1 0 0</forward>
      <upward>0 0 1</upward>
      <cp>0.04175 0 0</cp>
      <link_name>wave_glider_sub_wing1_link</link_name>
      <radial_symmetry>1</radial_symmetry>
      <topic>lift_drag</topic>
    </plugin>
    <plugin name="gz::sim::systems::FoilLiftDrag"
        filename="asv_sim2-foil-lift-drag-system">
      <a0>0.0</a0>
      <cla>6.2832</cla>
      <alpha_stall>0.1592</alpha_stall>
      <cla_stall>-0.7083</cla_stall>
      <cda>0.63662</cda>
      <area>0.24</area>
      <fluid_density>1000</fluid_density>
      <forward>1 0 0</forward>
      <upward>0 0 1</upward>
      <cp>0.04175 0 0</cp>
      <link_name>wave_glider_sub_wing2_link</link_name>
      <radial_symmetry>1</radial_symmetry>
      <topic>lift_drag</topic>
    </plugin>
    <plugin name="gz::sim::systems::FoilLiftDrag"
        filename="asv_sim2-foil-lift-drag-system">
      <a0>0.0</a0>
      <cla>6.2832</cla>
      <alpha_stall>0.1592</alpha_stall>
      <cla_stall>-0.7083</cla_stall>
      <cda>0.63662</cda>
      <area>0.24</area>
      <fluid_density>1000</fluid_density>
      <forward>1 0 0</forward>
      <upward>0 0 1</upward>
      <cp>0.04175 0 0</cp>
      <link_name>wave_glider_sub_wing3_link</link_name>
      <radial_symmetry>1</radial_symmetry>
      <topic>lift_drag</topic>
    </plugin>
    <plugin name="gz::sim::systems::FoilLiftDrag"
        filename="asv_sim2-foil-lift-drag-system">
      <a0>0.0</a0>
      <cla>6.2832</cla>
      <alpha_stall>0.1592</alpha_stall>
      <cla_stall>-0.7083</cla_stall>
      <cda>0.63662</cda>
      <area>0.24</area>
      <fluid_density>1000</fluid_density>
      <forward>1 0 0</forward>
      <upward>0 0 1</upward>
      <cp>0.04175 0 0</cp>
      <link_name>wave_glider_sub_wing4_link</link_name>
      <radial_symmetry>1</radial_symmetry>
      <topic>lift_drag</topic>
    </plugin>
    <plugin name="gz::sim::systems::FoilLiftDrag"
        filename="asv_sim2-foil-lift-drag-system">
      <a0>0.0</a0>
      <cla>6.2832</cla>
      <alpha_stall>0.1592</alpha_stall>
      <cla_stall>-0.7083</cla_stall>
      <cda>0.63662</cda>
      <area>0.24</area>
      <fluid_density>1000</fluid_density>
      <forward>1 0 0</forward>
      <upward>0 0 1</upward>
      <cp>0.04175 0 0</cp>
      <link_name>wave_glider_sub_wing5_link</link_name>
      <radial_symmetry>1</radial_symmetry>
      <topic>lift_drag</topic>
    </plugin>
    <plugin name="gz::sim::systems::FoilLiftDrag"
        filename="asv_sim2-foil-lift-drag-system">
      <a0>0.0</a0>
      <cla>6.2832</cla>
      <alpha_stall>0.1592</alpha_stall>
      <cla_stall>-0.7083</cla_stall>
      <cda>0.63662</cda>
      <area>0.24</area>
      <fluid_density>1000</fluid_density>
      <forward>1 0 0</forward>
      <upward>0 0 1</upward>
      <cp>0.04175 0 0</cp>
      <link_name>wave_glider_sub_wing6_link</link_name>
      <radial_symmetry>1</radial_symmetry>
      <topic>lift_drag</topic>
    </plugin>

    <!-- Hydrodynamics plugin -->
    <plugin
        filename="gz-waves1-hydrodynamics-system"  
        name="gz::sim::systems::Hydrodynamics">
      
        <enable>wave_glider::wave_glider_float_link</enable>
        <enable>wave_glider::wave_glider_sub_body_link</enable>
        <enable>wave_glider::wave_glider_sub_wing1_link</enable>
        <enable>wave_glider::wave_glider_sub_wing2_link</enable>
        <enable>wave_glider::wave_glider_sub_wing3_link</enable>
        <enable>wave_glider::wave_glider_sub_wing4_link</enable>
        <enable>wave_glider::wave_glider_sub_wing5_link</enable>
        <enable>wave_glider::wave_glider_sub_wing6_link</enable>
          
        <hydrodynamics>
          <!-- <damping_on>1</damping_on>
          <viscous_drag_on>1</viscous_drag_on> 
          <pressure_drag_on>1</pressure_drag_on> -->
        
          <!-- Linear and Angular Damping -->
          <!-- <cDampL1>1.0E-6</cDampL1>
          <cDampL2>1.0E-6</cDampL2>
          <cDampR1>1.0E-6</cDampR1>
          <cDampR2>1.0E-6</cDampR2> -->
    
          <!-- 'Pressure' Drag -->
          <!-- <cPDrag1>1.0E+2</cPDrag1> 
          <cPDrag2>1.0E+2</cPDrag2>
          <fPDrag>0.4</fPDrag>
          <cSDrag1>1.0E+2</cSDrag1>
          <cSDrag2>1.0E+2</cSDrag2>
          <fSDrag>0.4</fSDrag>
          <vRDrag>1.0</vRDrag> -->
        </hydrodynamics>
      </plugin>

  </model>
</sdf>
